Workbook

Sheet Lookups
A1: Support Level | B1: Score | D1: Priority | E1: Suggested Weight
A2: OOB (out-of-box) | B2: 5 | D2: Must | E2: 3
A3: Configurable | B3: 4 | D3: Should | E3: 2
A4: Custom / Professional Services | B4: 2 | D4: Could | E4: 1
A5: Roadmap | B5: 1
A6: Not supported | B6: 0
A7: N/A

Sheet Functional Test Suite
A1: Test ID | B1: Tier | C1: Category | D1: Subcategory | E1: Capability / Feature | F1: Test Scenario (what to ask / do) | G1: Pass Criteria | H1: Evidence to Capture | I1: Test Method | J1: Priority | K1: Weight | L1: Source Req IDs | M1: Vendor Support Level | N1: Score | O1: Weighted Score | P1: Notes / Limitations
A2: F-001 | B2: Core | C2: 1. Charger and Network Management | D2: 1.1 Charger Connectivity and Protocol Support | E2: Charger compatibility / hardware agnostic onboarding | F2: Connect at least 2–3 different EVSE models (AC + DC) and verify onboarding/provisioning without custom firmware per model. | G2: EVSEs connect successfully; core operations (status, start/stop, meter values) work consistently across models. | H2: List of supported EVSE models; screenshot of EVSE details; OCPP logs showing successful boot/heartbeat. | I2: POC + Docs | J2: Must | K2: 3 | L2: 1.1.1 | N2: =IFERROR(VLOOKUP(M2,Lookups!$A$2:$B$7,2,FALSE),"") | O2: =IF(N2="","",K2*N2)
A3: F-002 | B3: Core | C3: 1. Charger and Network Management | D3: 1.1 Charger Connectivity and Protocol Support | E3: OCPP protocol support (1.6J + 2.0.1) and certification evidence | F3: Ask vendor to demonstrate OCPP 1.6J and OCPP 2.0.1 operation (or simulator) and provide certification/interop proof. | G3: Evidence of OCPP certification/interop; successful OCPP connection and basic operations on both versions (where applicable). | H3: Certification documents; test logs; screenshots of protocol configuration. | I3: Docs + Demo | J3: Must | K3: 3 | L3: 1.1.2 | N3: =IFERROR(VLOOKUP(M3,Lookups!$A$2:$B$7,2,FALSE),"") | O3: =IF(N3="","",K3*N3)
A4: F-003 | B4: Extended | C4: 1. Charger and Network Management | D4: 1.1 Charger Connectivity and Protocol Support | E4: Remote firmware management for chargers | F4: Run a firmware update campaign on a test EVSE (single + bulk). Track progress, handle failure, and verify final version. | G4: Firmware can be scheduled/triggered remotely; status and errors are visible; failures are handled without bricking devices. | H4: Campaign screen; EVSE firmware version before/after; failure log example. | I4: POC + Demo | J4: Should | K4: 2 | L4: 1.1.3 | N4: =IFERROR(VLOOKUP(M4,Lookups!$A$2:$B$7,2,FALSE),"") | O4: =IF(N4="","",K4*N4)
A5: F-004 | B5: Core | C5: 1. Charger and Network Management | D5: 1.2 Real-time Monitoring and Control | E5: Real-time EVSE status & telemetry ingestion | F5: Validate that EVSE state changes (Available/Charging/Faulted/Offline) propagate to CPMS in near real time and are historically traceable. | G5: Status updates appear within agreed latency; data is consistent with charger/HMI; history is accessible. | H5: Screenshots of dashboard + EVSE timeline; sample event stream/logs. | I5: POC | J5: Must | K5: 3 | L5: 1.2.1, 1.2.2, 1.2.6 | N5: =IFERROR(VLOOKUP(M5,Lookups!$A$2:$B$7,2,FALSE),"") | O5: =IF(N5="","",K5*N5)
A6: F-005 | B6: Core | C6: 1. Charger and Network Management | D6: 1.2 Real-time Monitoring and Control | E6: Remote operational commands (restart, unlock, availability) | F6: Send remote commands (restart charger, unlock connector/cable, set inoperative/operative) and verify the EVSE executes them and CPMS records outcome. | G6: Commands succeed (or return clear error); outcomes are logged; safety checks and permissions apply. | H6: Command audit log; EVSE behavior evidence; error handling example. | I6: POC | J6: Must | K6: 3 | L6: 1.2.3, 1.2.5, 1.2.7 | N6: =IFERROR(VLOOKUP(M6,Lookups!$A$2:$B$7,2,FALSE),"") | O6: =IF(N6="","",K6*N6)
A7: F-006 | B7: Extended | C7: 1. Charger and Network Management | D7: 1.2 Real-time Monitoring and Control | E7: Network operations dashboard | F7: Review the operations dashboard for fleet overview, filtering (site, model, status), and drill-down to a single EVSE/connector. | G7: Dashboard provides actionable view and supports filtering/drill-down; key KPIs visible (uptime, sessions, faults). | H7: Dashboard screenshots; list of available filters/exports. | I7: Demo | J7: Should | K7: 2 | L7: 1.2.4 | N7: =IFERROR(VLOOKUP(M7,Lookups!$A$2:$B$7,2,FALSE),"") | O7: =IF(N7="","",K7*N7)
A8: F-007 | B8: Core | C8: 1. Charger and Network Management | D8: 1.3 Charge Point Management and Definition | E8: EVSE provisioning (manual + bulk) and property management | F8: Create a site and add EVSEs via UI and via bulk import/API. Update key properties (name, power, access type, timezone). | G8: Provisioning works end-to-end; changes are validated and versioned; bulk import reports errors clearly. | H8: Import template; success/error report; EVSE detail pages. | I8: POC + Demo | J8: Must | K8: 3 | L8: 1.3.1 | N8: =IFERROR(VLOOKUP(M8,Lookups!$A$2:$B$7,2,FALSE),"") | O8: =IF(N8="","",K8*N8)
A9: F-008 | B9: Extended | C9: 1. Charger and Network Management | D9: 1.3 Charge Point Management and Definition | E9: Connector/EVSE modeling (connectors, dynamic satellites, metadata) | F9: Model an EVSE with multiple connectors and (if relevant) satellite/dynamic connectors. Verify connector-level status and session data. | G9: CPMS supports connector-level entities; dynamic connector counts are supported or clearly constrained. | H9: EVSE/connector model screenshots; sample sessions per connector. | I9: Demo | J9: Should | K9: 2 | L9: 1.3.2, 1.3.11 | N9: =IFERROR(VLOOKUP(M9,Lookups!$A$2:$B$7,2,FALSE),"") | O9: =IF(N9="","",K9*N9)
A10: F-009 | B10: Extended | C10: 1. Charger and Network Management | D10: 1.3 Charge Point Management and Definition | E10: Access types and private/home charger association | F10: Configure public vs private vs fleet EVSEs and associate a private/home charger to a specific driver/account. | G10: Access rules enforce who can start sessions; private/home association impacts billing/reporting correctly. | H10: Configuration screenshots; access denied/allowed evidence. | I10: POC + Demo | J10: Should | K10: 2 | L10: 1.3.3, 1.3.4 | N10: =IFERROR(VLOOKUP(M10,Lookups!$A$2:$B$7,2,FALSE),"") | O10: =IF(N10="","",K10*N10)
A11: F-010 | B11: Extended | C11: 1. Charger and Network Management | D11: 1.3 Charge Point Management and Definition | E11: Location and operating schedule management | F11: Edit site/EVSE address, geo-coordinates, and operating hours / time schedules (including exceptions). | G11: Location updates reflect in discovery/reporting; schedules can be managed and enforced (if applicable). | H11: Site details; schedule calendar; app/map display evidence. | I11: Demo | J11: Should | K11: 2 | L11: 1.3.5, 1.3.6 | N11: =IFERROR(VLOOKUP(M11,Lookups!$A$2:$B$7,2,FALSE),"") | O11: =IF(N11="","",K11*N11)
A12: F-011 | B12: Extended | C12: 1. Charger and Network Management | D12: 1.3 Charge Point Management and Definition | E12: Configuration templates, compare & apply | F12: Compare two EVSE configurations, create a template/preset, and apply it to an EVSE and to a group. | G12: Differences can be compared; presets can be applied safely; resulting config matches expected values. | H12: Comparison view; template definition; before/after config export. | I12: Demo | J12: Should | K12: 2 | L12: 1.3.8, 1.3.9, 1.3.10 | N12: =IFERROR(VLOOKUP(M12,Lookups!$A$2:$B$7,2,FALSE),"") | O12: =IF(N12="","",K12*N12)
A13: F-012 | B13: Extended | C13: 1. Charger and Network Management | D13: 1.3 Charge Point Management and Definition | E13: Manual status override with permissions | F13: Manually set an EVSE/connector status (e.g., Inoperative) and confirm it is permission-gated and recorded. | G13: Only authorized roles can override; changes are logged; status is visible across UI/API. | H13: Audit entry; role permission settings; UI status evidence. | I13: POC + Demo | J13: Should | K13: 2 | L13: 1.3.7 | N13: =IFERROR(VLOOKUP(M13,Lookups!$A$2:$B$7,2,FALSE),"") | O13: =IF(N13="","",K13*N13)
... A90: F-089 | B90: Extended | C90: 6. Mobile App Functionality (Drivers) | D90: 6.6 Advanced Mobile App Functionality | E90: Issue reporting from app (charger faults) to support workflow | F90: Report an issue from the app for a specific charger and validate it creates a support case with context. | G90: Issue report includes charger/session context; support receives it; status updates possible. | H90: Issue report screenshot; created ticket/case evidence. | I90: POC | J90: Should | K90: 2 | L90: 6.6.3, 6.7.1 | N90: =IFERROR(VLOOKUP(M90,Lookups!$A$2:$B$7,2,FALSE),"") | O90: =IF(N90="","",K90*N90)
A91: F-090 | B91: Extended | C91: 7. Reservations | E91: Create a reservation with time-slot selection | F91: From app/portal, reserve a charger for a future time using available time slots. | G91: Reservation is created; calendar shows availability; conflicts are prevented. | H91: Reservation screen; calendar view; confirmation message. | I91: POC | J91: Should | K91: 2 | L91: 7.1 | N91: =IFERROR(VLOOKUP(M91,Lookups!$A$2:$B$7,2,FALSE),"") | O91: =IF(N91="","",K91*N91)
A92: F-091 | B92: Extended | C92: 7. Reservations | E92: Reservation rules (max duration, lead time, grace periods) | F92: Configure max reservation duration and any lead time/grace period rules; validate enforcement. | G92: Rules are configurable and enforced consistently. | H92: Rule configuration; attempted invalid booking evidence. | I92: Demo | J92: Should | K92: 2 | L92: 7.2 | N92: =IFERROR(VLOOKUP(M92,Lookups!$A$2:$B$7,2,FALSE),"") | O92: =IF(N92="","",K92*N92)
A93: F-092 | B93: Extended | C93: 7. Reservations | E93: Reservation notifications and reminders | F93: Validate notifications for upcoming reservation start and arrival reminders. | G93: Notifications arrive with correct timing and content; user can manage preferences if available. | H93: Notification screenshot; preference settings. | I93: POC | J93: Could | K93: 1 | L93: 7.3 | N93: =IFERROR(VLOOKUP(M93,Lookups!$A$2:$B$7,2,FALSE),"") | O93: =IF(N93="","",K93*N93)
A94: F-093 | B94: Extended | C94: 7. Reservations | E94: Reservation management (view, cancel) for customer and customer service | F94: View and cancel reservations as a user and as customer service; validate audit trail. | G94: Both user and CS can view/cancel per permissions; cancellation policy applied. | H94: Reservation list; cancellation record; audit log. | I94: POC | J94: Should | K94: 2 | L94: 7.4, 7.5 | N94: =IFERROR(VLOOKUP(M94,Lookups!$A$2:$B$7,2,FALSE),"") | O94: =IF(N94="","",K94*N94)
A95: F-094 | B95: Extended | C95: 7. Reservations | E95: Reservation exclusivity and fee policies | F95: Verify reserved chargers show 'Reserved' status and are blocked for others; validate reservation cost/no-show/cancellation fees. | G95: Reserved state prevents others from starting; fees/penalties can be configured and billed correctly. | H95: Reserved status on map; blocked start attempt; fee line-item on receipt. | I95: POC | J95: Should | K95: 2 | L95: 7.6, 7.7, 8.8, 8.11, 8.12 | N95: =IFERROR(VLOOKUP(M95,Lookups!$A$2:$B$7,2,FALSE),"") | O95: =IF(N95="","",K95*N95)
A96: F-095 | B96: Core | C96: 8. Flexible Tariff, Pricing and Billing Plans | E96: Tariff component model (energy, time, session fee, min/max, overstay, parking) | F96: Configure a tariff with multiple components (kWh rate + session fee + overstay/parking). Run a session and validate billing. | G96: Billing matches configured components; constraints (min/max) are applied; receipt shows components. | H96: Tariff config; sample receipt; CDR rating breakdown. | I96: POC | J96: Must | K96: 3 | L96: 8.1, 8.4, 8.5, 8.6, 8.7 | N96: =IFERROR(VLOOKUP(M96,Lookups!$A$2:$B$7,2,FALSE),"") | O96: =IF(N96="","",K96*N96)
A97: F-096 | B97: Extended | C97: 8. Flexible Tariff, Pricing and Billing Plans | E97: Time-based and day-of-week pricing (ToD/DoW) | F97: Create time-of-day/day-of-week pricing variations and validate rating across boundaries. | G97: Tariff schedule is supported; session is correctly segmented and billed. | H97: Tariff schedule; segmented receipt/CDR. | I97: POC | J97: Should | K97: 2 | L97: 8.3, 2.7.1 | N97: =IFERROR(VLOOKUP(M97,Lookups!$A$2:$B$7,2,FALSE),"") | O97: =IF(N97="","",K97*N97)
A98: F-097 | B98: Extended | C98: 8. Flexible Tariff, Pricing and Billing Plans | E98: Reservation and penalty fees (initial, per-minute, late/no-show, cancellation) | F98: Configure reservation fee policies and validate charges for late arrival/no-show/cancel. | G98: Fees are configurable and applied as expected; shown to user before charging where required. | H98: Fee policy config; receipt line items; tariff display evidence. | I98: POC | J98: Should | K98: 2 | L98: 8.8, 8.9, 8.10, 8.11, 8.12, 7.7 | N98: =IFERROR(VLOOKUP(M98,Lookups!$A$2:$B$7,2,FALSE),"") | O98: =IF(N98="","",K98*N98)
A99: F-098 | B99: Extended | C99: 8. Flexible Tariff, Pricing and Billing Plans | E99: Interruptible tariffs and pre-emption | F99: Demonstrate interruptible tariff behavior: temporarily suspend charging due to technical/commercial reasons and resume. | G99: Suspension/resume is supported; user messaging exists; billing is correct and auditable. | H99: Control log; user notification; session record. | I99: Demo | J99: Could | K99: 1 | L99: 8.13, 8.14, 8.15 | N99: =IFERROR(VLOOKUP(M99,Lookups!$A$2:$B$7,2,FALSE),"") | O99: =IF(N99="","",K99*N99)
A100: F-099 | B100: Extended | C100: 8. Flexible Tariff, Pricing and Billing Plans | E100: ToU tariff upload (hourly) and use in billing/optimization | F100: Upload hourly ToU energy tariff and validate it is used for billing and/or energy management decisions. | G100: Hourly tariff import works; updates are versioned; rating is correct. | H100: Upload file; tariff table; rated session evidence. | I100: POC | J100: Should | K100: 2 | L100: 8.16, 3.3.1 | N100: =IFERROR(VLOOKUP(M100,Lookups!$A$2:$B$7,2,FALSE),"") | O100: =IF(N100="","",K100*N100)
A101: F-100 | B101: Extended | C101: 8. Flexible Tariff, Pricing and Billing Plans | E101: Dynamic energy price-based tariffs | F101: Demonstrate how dynamic pricing inputs are ingested and applied (e.g., market price feed) and how customers are informed. | G101: Dynamic pricing is supported or clear constraints; customer transparency is handled. | H101: Integration doc; sample price update; session bill. | I101: Docs + Demo | J101: Could | K101: 1 | L101: 8.17 | N101: =IFERROR(VLOOKUP(M101,Lookups!$A$2:$B$7,2,FALSE),"") | O101: =IF(N101="","",K101*N101)
A102: F-101 | B102: Core | C102: 8. Flexible Tariff, Pricing and Billing Plans | E102: Tariff assignment and eligibility rules (by charger/group/user/partner) | F102: Assign default tariffs per charger and group; create eligibility rules for customer groups and roaming partners. | G102: Assignment and precedence are clear; correct tariff is applied for different users/partners. | H102: Assignment screens; eligibility rules; test sessions evidence. | I102: POC | J102: Must | K102: 3 | L102: 8.2, 8.25, 9.7 | N102: =IFERROR(VLOOKUP(M102,Lookups!$A$2:$B$7,2,FALSE),"") | O102: =IF(N102="","",K102*N102)
... A110: F-109 | B110: Extended | C110: 9. Roaming | E110: Roaming monitoring dashboard and detailed logs | F110: Review centralized dashboard for roaming sessions (status, failures) and ability to access detailed per-session logs. | G110: Operational visibility exists; failures are actionable; logs support audits. | H110: Dashboard screenshots; sample session log export. | I110: Demo | J110: Should | K110: 2 | L110: 9.9, 9.10 | N110: =IFERROR(VLOOKUP(M110,Lookups!$A$2:$B$7,2,FALSE),"") | O110: =IF(N110="","",K110*N110)
A111: F-110 | B111: Core | C111: 10. Driver Invoice Payment | D111: 10.1 Driver payment options | E111: Supported payment options (cards, wallets, app, roaming billing) | F111: Demonstrate accepted payment methods including cards, Apple/Google Pay, in-app payments, and roaming billing flows. | G111: Payment method matrix is clear; at least one end-to-end payment is demonstrated; roaming billing is supported if required. | H111: Payment method list; demo receipts; gateway configuration. | I111: Demo | J111: Must | K111: 3 | L111: 10.1.1 | N111: =IFERROR(VLOOKUP(M111,Lookups!$A$2:$B$7,2,FALSE),"") | O111: =IF(N111="","",K111*N111)
A112: F-111 | B112: Core | C112: 10. Driver Invoice Payment | D112: 10.1 Driver payment options | E112: Billing models (prepaid, pay-as-you-go, postpaid invoicing) | F112: Configure and test prepaid top-up, immediate payment, and monthly postpaid invoicing for drivers. | G112: Each model is supported; transitions and edge cases are handled; invoices are generated correctly. | H112: Plan configuration; invoice examples; wallet balances. | I112: POC | J112: Must | K112: 3 | L112: 10.1.2, 10.2.3 | N112: =IFERROR(VLOOKUP(M112,Lookups!$A$2:$B$7,2,FALSE),"") | O112: =IF(N112="","",K112*N112)
A113: F-112 | B113: Core | C113: 10. Driver Invoice Payment | D113: 10.2 Driver Billing Models and Payment Flows | E113: Automatic invoice payment (in-app + customer support assisted) | F113: Generate an invoice and pay automatically in-app; validate CS-assisted payment flow and audit logging. | G113: Invoices can be paid via app and CS; payments are reconciled; audit trail exists. | H113: Invoice status before/after; payment confirmation; audit log. | I113: POC | J113: Must | K113: 3 | L113: 10.2.1 | N113: =IFERROR(VLOOKUP(M113,Lookups!$A$2:$B$7,2,FALSE),"") | O113: =IF(N113="","",K113*N113)
A114: F-113 | B114: Extended | C114: 10. Driver Invoice Payment | D114: 10.2 Driver Billing Models and Payment Flows | E114: Prepaid auto top-up on insufficient funds | F114: With prepaid plan, attempt session with low balance and validate auto top-up/transfer behavior and failure handling. | G114: Auto top-up triggers per configured threshold; failures are handled gracefully; user notified. | H114: Top-up settings; gateway/bank transfer logs; notifications. | I114: POC | J114: Should | K114: 2 | L114: 10.2.2 | N114: =IFERROR(VLOOKUP(M114,Lookups!$A$2:$B$7,2,FALSE),"") | O114: =IF(N114="","",K114*N114)
A115: F-114 | B115: Core | C115: 10. Driver Invoice Payment | D115: 10.2 Driver Billing Models and Payment Flows | E115: Balance/statement visibility for drivers | F115: Verify drivers can view available balances and transaction history in app/portal. | G115: Balance is accurate and updates in near real-time; history is exportable if required. | H115: Screenshots; sample export. | I115: Demo | J115: Must | K115: 3 | L115: 10.2.4 | N115: =IFERROR(VLOOKUP(M115,Lookups!$A$2:$B$7,2,FALSE),"") | O115: =IF(N115="","",K115*N115)
A116: F-115 | B116: Extended | C116: 10. Driver Invoice Payment | D116: 10.3 Customer Account Management & Dispute Resolution | E116: Invoice dispute workflow (review logs, refunds/credits) | F116: Create a dispute for an invoice, review detailed session logs as CS, and issue refund/credit. | G116: Dispute can be logged and tracked; CS has necessary evidence; refunds/credits are auditable. | H116: Dispute record; refund/credit note; session logs. | I116: POC | J116: Should | K116: 2 | L116: 10.3.1 | N116: =IFERROR(VLOOKUP(M116,Lookups!$A$2:$B$7,2,FALSE),"") | O116: =IF(N116="","",K116*N116)
A117: F-116 | B117: Extended | C117: 10. Driver Invoice Payment | D117: 10.3 Customer Account Management & Dispute Resolution | E117: Adjustments: cancel invoice, write-off, third-party payer / sponsorship | F117: Demonstrate manual cancel/write-off, and one customer paying for another or sponsor/OEM-funded charging. | G117: Adjustments are controlled by role; accounting is correct; audit trail exists. | H117: Adjustment screens; audit logs; invoice examples. | I117: Demo | J117: Should | K117: 2 | L117: 10.3.2, 10.3.3, 10.3.4, 10.3.5 | N117: =IFERROR(VLOOKUP(M117,Lookups!$A$2:$B$7,2,FALSE),"") | O117: =IF(N117="","",K117*N117)
A118: F-117 | B118: Core | C118: 10. Driver Invoice Payment | D118: 10.4 Payment Methods & Integration | E118: Payment gateway and payment terminal integrations | F118: Show supported gateways out-of-box (e.g., Stripe/Adyen) and support for terminals (Payter/Nayax/etc). | G118: Integrations exist and are documented; certification/compliance considerations are clear. | H118: Gateway list; terminal integration doc; architecture diagram. | I118: Docs + Demo | J118: Must | K118: 3 | L118: 10.4.1, 10.3.6 | N118: =IFERROR(VLOOKUP(M118,Lookups!$A$2:$B$7,2,FALSE),"") | O118: =IF(N118="","",K118*N118)
A119: F-118 | B119: Extended | C119: 10. Driver Invoice Payment | D119: 10.4 Payment Methods & Integration | E119: CTEP / tariff display transparency compliance | F119: Demonstrate how tariffs are displayed before/during/after session on charger HMI (if supported) and in receipts. | G119: Tariff transparency requirements can be met; receipts include required information. | H119: HMI screen photos/simulator; detailed receipt sample. | I119: Demo | J119: Should | K119: 2 | L119: 10.3.7 | N119: =IFERROR(VLOOKUP(M119,Lookups!$A$2:$B$7,2,FALSE),"") | O119: =IF(N119="","",K119*N119)
A120: F-119 | B120: Core | C120: 11. Reporting and Analytics | E120: Transaction and revenue reporting (trend + detail) | F120: Generate transaction and revenue reports with trend views over time and drill-down to sessions/invoices. | G120: Reports are accurate; support filtering and export; reconciles with billing totals. | H120: Sample report exports; reconciliation evidence. | I120: Demo | J120: Must | K120: 3 | L120: 11.1, 11.2 | N120: =IFERROR(VLOOKUP(M120,Lookups!$A$2:$B$7,2,FALSE),"") | O120: =IF(N120="","",K120*N120)
A121: F-120 | B121: Extended | C121: 11. Reporting and Analytics | E121: Segmentation and breakdown reporting (site, charger, customer, tariff) | F121: Filter reports by site/charger/customer/tariff and show breakdowns (payment methods, customer groups). | G121: Segmentation works; performance is acceptable; exports preserve filters. | H121: Filtered report screenshots; export file. | I121: Demo | J121: Should | K121: 2 | L121: 11.3, 11.6 | N121: =IFERROR(VLOOKUP(M121,Lookups!$A$2:$B$7,2,FALSE),"") | O121: =IF(N121="","",K121*N121)
A122: F-121 | B122: Extended | C122: 11. Reporting and Analytics | E122: Faults and uptime reporting | F122: Generate reports for charger faults, availability, MTTR, and uptime by model/site. | G122: Fault reports align with alerting system; key KPIs available. | H122: Fault report; raw fault log reference. | I122: Demo | J122: Should | K122: 2 | L122: 11.4, 1.5.5 | N122: =IFERROR(VLOOKUP(M122,Lookups!$A$2:$B$7,2,FALSE),"") | O122: =IF(N122="","",K122*N122)
A123: F-122 | B123: Extended | C123: 11. Reporting and Analytics | E123: Ticket/issue reporting | F123: Report on issues/tickets (if integrated) including trends, SLA metrics, and categories. | G123: Issue reporting is available or can be integrated; exports supported. | H123: Issue report; ticketing integration evidence. | I123: Demo | J123: Could | K123: 1 | L123: 11.5, 1.5.11 | N123: =IFERROR(VLOOKUP(M123,Lookups!$A$2:$B$7,2,FALSE),"") | O123: =IF(N123="","",K123*N123)
...

Sheet Non-Functional Test Suite
A1: Test ID | B1: Tier | C1: Category | D1: Subcategory | E1: Capability / Feature | F1: Test Scenario (what to ask / do) | G1: Pass Criteria | H1: Evidence to Capture | I1: Test Method | J1: Priority | K1: Weight | L1: Source Req IDs | M1: Vendor Support Level | N1: Score | O1: Weighted Score | P1: Notes / Limitations
A2: NF-001 | B2: Core | C2: 1.Certifications, governance, and privacy compliance | E2: Security certifications (ISO 27001) and scope | F2: Request ISO 27001 certificate and Statement of Applicability; confirm scope includes CPMS service and supporting processes. | G2: Valid certificate; scope is relevant; audit date is current; exceptions/controls are understood. | H2: ISO certificate; SoA summary; audit report executive summary (if shareable). | I2: Docs | J2: Must | K2: 3 | L2: 1.1 | N2: =IFERROR(VLOOKUP(M2,Lookups!$A$2:$B$7,2,FALSE),"") | O2: =IF(N2="","",K2*N2)
A3: NF-002 | B3: Extended | C3: 1.Certifications, governance, and privacy compliance | E3: SOC reports (SOC 1 / SOC 2) availability | F3: Request SOC 1 and/or SOC 2 Type 2 report (preferred). Validate coverage of security, availability, confidentiality. | G3: Recent SOC report exists; exceptions have remediation plan; customer can review under NDA. | H3: SOC report cover letter; bridge letter; remediation plan. | I3: Docs | J3: Should | K3: 2 | L3: 1.2, 1.3 | N3: =IFERROR(VLOOKUP(M3,Lookups!$A$2:$B$7,2,FALSE),"") | O3: =IF(N3="","",K3*N3)
A4: NF-003 | B4: Core | C4: 1.Certifications, governance, and privacy compliance | E4: Cybersecurity governance program | F4: Review vendor security program: policies, risk management, third-party risk, security training. | G4: Documented program exists; roles/responsibilities defined; evidence of regular reviews. | H4: Security policy index; org chart; training metrics. | I4: Docs + Interview | J4: Must | K4: 3 | L4: 1.4 | N4: =IFERROR(VLOOKUP(M4,Lookups!$A$2:$B$7,2,FALSE),"") | O4: =IF(N4="","",K4*N4)
A5: NF-004 | B5: Core | C5: 2. Security - Identity & Access Management | E5: SSO integration (SAML/OIDC) | F5: Validate SSO support and test with a standard IdP in a sandbox (Okta/Azure AD). | G5: SSO works; supports JIT provisioning or SCIM; role mapping supported. | H5: SSO config guide; test login evidence; SCIM docs. | I5: POC + Docs | J5: Must | K5: 3 | L5: 2.1 | N5: =IFERROR(VLOOKUP(M5,Lookups!$A$2:$B$7,2,FALSE),"") | O5: =IF(N5="","",K5*N5)
A6: NF-005 | B6: Core | C6: 2. Security - Identity & Access Management | E6: MFA support and policy enforcement | F6: Validate MFA methods (TOTP, push, SMS) and ability to enforce MFA for privileged roles. | G6: MFA is available and enforceable; recovery controls are secure. | H6: MFA policy settings; enrollment evidence; recovery process description. | I6: POC + Docs | J6: Must | K6: 3 | L6: 2.2 | N6: =IFERROR(VLOOKUP(M6,Lookups!$A$2:$B$7,2,FALSE),"") | O6: =IF(N6="","",K6*N6)
A7: NF-006 | B7: Core | C7: 2. Security - Identity & Access Management | E7: RBAC and least-privilege model | F7: Review RBAC model and test permission boundaries for admin, operator, support roles. | G7: Least-privilege achievable; permissions are granular; audit trail exists. | H7: Role matrix; access test results; audit logs. | I7: POC | J7: Must | K7: 3 | L7: 2.3 | N7: =IFERROR(VLOOKUP(M7,Lookups!$A$2:$B$7,2,FALSE),"") | O7: =IF(N7="","",K7*N7)
A8: NF-007 | B8: Extended | C8: 2. Security - Identity & Access Management | E8: Password policy and account protections | F8: Review password policy controls (length/complexity/history/expiry) and brute-force protections (lockout, rate limiting). | G8: Password policy configurable; protections in place; aligns with company policy. | H8: Security settings screenshots; policy docs. | I8: Docs + Demo | J8: Should | K8: 2 | L8: 2.4 | N8: =IFERROR(VLOOKUP(M8,Lookups!$A$2:$B$7,2,FALSE),"") | O8: =IF(N8="","",K8*N8)
A9: NF-008 | B9: Extended | C9: 2. Security - Identity & Access Management | E9: IP allowlisting for sensitive roles | F9: Validate ability to restrict admin access by IP ranges and log violations. | G9: IP restrictions enforce properly; audit logs show blocked attempts. | H9: IP allowlist config; blocked login evidence. | I9: POC | J9: Should | K9: 2 | L9: 2.5 | N9: =IFERROR(VLOOKUP(M9,Lookups!$A$2:$B$7,2,FALSE),"") | O9: =IF(N9="","",K9*N9)
A10: NF-009 | B10: Core | C10: 3. Security - Systems Monitoring | E10: Security event logging coverage | F10: Review which events are logged (auth, admin actions, exceptions, firmware changes) and how logs are protected. | G10: Comprehensive logging; integrity protections; access controls. | H10: Logging specification; sample logs; access control description. | I10: Docs | J10: Must | K10: 3 | L10: 3.1 | N10: =IFERROR(VLOOKUP(M10,Lookups!$A$2:$B$7,2,FALSE),"") | O10: =IF(N10="","",K10*N10)
A11: NF-010 | B11: Extended | C11: 3. Security - Systems Monitoring | E11: Log retention and review process | F11: Confirm retention periods and review cadence; validate time synchronization strategy (NTP). | G11: Retention meets requirements; reviews occur; time sync is consistent. | H11: Retention policy; NTP architecture; audit evidence of reviews. | I11: Docs + Interview | J11: Should | K11: 2 | L11: 3.2, 3.3 | N11: =IFERROR(VLOOKUP(M11,Lookups!$A$2:$B$7,2,FALSE),"") | O11: =IF(N11="","",K11*N11)
A12: NF-011 | B12: Core | C12: 3. Security - Systems Monitoring | E12: Monitoring and alerting (exceptions, degradation) | F12: Walk through monitoring stack (APM, metrics, alerts) and demonstrate alert routing and escalation. | G12: Monitoring detects degradations; alerts are actionable; on-call process exists. | H12: Monitoring dashboard screenshots; sample alert; runbook. | I12: Demo + Interview | J12: Must | K12: 3 | L12: 3.4 | N12: =IFERROR(VLOOKUP(M12,Lookups!$A$2:$B$7,2,FALSE),"") | O12: =IF(N12="","",K12*N12)
A13: NF-012 | B13: Extended | C13: 4. Network Security | E13: Network hardening standards | F13: Review baseline configuration standards for network devices and how changes are controlled. | G13: Hardened baselines exist; changes are approved and auditable. | H13: Network baseline docs; change control evidence. | I13: Docs | J13: Should | K13: 2 | L13: 4.1 | N13: =IFERROR(VLOOKUP(M13,Lookups!$A$2:$B$7,2,FALSE),"") | O13: =IF(N13="","",K13*N13)
... A49: NF-048 | B49: Extended | C49: 15. Post Implementation Support | E49: Change management and release communications | F49: Review change management process for planned/unplanned changes and customer communications. | G49: Process is documented; customers receive timely comms; backward compatibility addressed. | H49: Change management SOP; sample release notes; incident comms template. | I49: Docs | J49: Should | K49: 2 | L49: 15.6 | N49: =IFERROR(VLOOKUP(M49,Lookups!$A$2:$B$7,2,FALSE),"") | O49: =IF(N49="","",K49*N49)

Sheet Summary
A1: How to use this workbook
A2: 1) Filter by Tier = Core to focus on must-have capabilities.
A3: 2) For each test case, set 'Vendor Support Level' (dropdown).
A4: 3) Score and Weighted Score calculate automatically.
A5: 4) Use the category summaries below to compare vendors or track progress.
A7: Support Level → Score mapping:
A8: OOB (out-of-box)=5 | Configurable=4 | Custom/PS=2 | Roadmap=1 | Not supported=0 | N/A=blank
A10: Functional Category Summary
A11: Category | B11: # Tests | C11: # Scored | D11: Total Weight | E11: Total Weighted Score | F11: Weighted Avg
A12: 1. Charger and Network Management | B12: =COUNTIF('Functional Test Suite'!$C:$C,$A12) -> 22 | C12: =COUNTIFS('Functional Test Suite'!$C:$C,$A12,'Functional Test Suite'!$M:$M,"<>") -> 0 | D12: =SUMIF('Functional Test Suite'!$C:$C,$A12,'Functional Test Suite'!$K:$K) -> 51 | E12: =SUMIF('Functional Test Suite'!$C:$C,$A12,'Functional Test Suite'!$O:$O) -> 0 | F12: =IF(D12=0,"",E12/D12) -> 0
A13: 2. Charging Session Management & CDR | B13: =COUNTIF('Functional Test Suite'!$C:$C,$A13) -> 10 | C13: =COUNTIFS('Functional Test Suite'!$C:$C,$A13,'Functional Test Suite'!$M:$M,"<>") -> 0 | D13: =SUMIF('Functional Test Suite'!$C:$C,$A13,'Functional Test Suite'!$K:$K) -> 26 | E13: =SUMIF('Functional Test Suite'!$C:$C,$A13,'Functional Test Suite'!$O:$O) -> 0 | F13: =IF(D13=0,"",E13/D13) -> 0
A14: 3. Smart Energy Management | B14: =COUNTIF('Functional Test Suite'!$C:$C,$A14) -> 21 | C14: =COUNTIFS('Functional Test Suite'!$C:$C,$A14,'Functional Test Suite'!$M:$M,"<>") -> 0 | D14: =SUMIF('Functional Test Suite'!$C:$C,$A14,'Functional Test Suite'!$K:$K) -> 31 | E14: =SUMIF('Functional Test Suite'!$C:$C,$A14,'Functional Test Suite'!$O:$O) -> 0 | F14: =IF(D14=0,"",E14/D14) -> 0
A15: 4. Authentication Methods | B15: =COUNTIF('Functional Test Suite'!$C:$C,$A15) -> 8 | C15: =COUNTIFS('Functional Test Suite'!$C:$C,$A15,'Functional Test Suite'!$M:$M,"<>") -> 0 | D15: =SUMIF('Functional Test Suite'!$C:$C,$A15,'Functional Test Suite'!$K:$K) -> 18 | E15: =SUMIF('Functional Test Suite'!$C:$C,$A15,'Functional Test Suite'!$O:$O) -> 0 | F15: =IF(D15=0,"",E15/D15) -> 0
A16: 5. Driver Management | B16: =COUNTIF('Functional Test Suite'!$C:$C,$A16) -> 10 | C16: =COUNTIFS('Functional Test Suite'!$C:$C,$A16,'Functional Test Suite'!$M:$M,"<>") -> 0 | D16: =SUMIF('Functional Test Suite'!$C:$C,$A16,'Functional Test Suite'!$K:$K) -> 26 | E16: =SUMIF('Functional Test Suite'!$C:$C,$A16,'Functional Test Suite'!$O:$O) -> 0 | F16: =IF(D16=0,"",E16/D16) -> 0
A17: 6. Mobile App Functionality (Drivers) | B17: =COUNTIF('Functional Test Suite'!$C:$C,$A17) -> 18 | C17: =COUNTIFS('Functional Test Suite'!$C:$C,$A17,'Functional Test Suite'!$M:$M,"<>") -> 0 | D17: =SUMIF('Functional Test Suite'!$C:$C,$A17,'Functional Test Suite'!$K:$K) -> 39 | E17: =SUMIF('Functional Test Suite'!$C:$C,$A17,'Functional Test Suite'!$O:$O) -> 0 | F17: =IF(D17=0,"",E17/D17) -> 0
A18: 7. Reservations | B18: =COUNTIF('Functional Test Suite'!$C:$C,$A18) -> 5 | C18: =COUNTIFS('Functional Test Suite'!$C:$C,$A18,'Functional Test Suite'!$M:$M,"<>") -> 0 | D18: =SUMIF('Functional Test Suite'!$C:$C,$A18,'Functional Test Suite'!$K:$K) -> 9 | E18: =SUMIF('Functional Test Suite'!$C:$C,$A18,'Functional Test Suite'!$O:$O) -> 0 | F18: =IF(D18=0,"",E18/D18) -> 0
A19: 8. Flexible Tariff, Pricing and Billing Plans | B19: =COUNTIF('Functional Test Suite'!$C:$C,$A19) -> 9 | C19: =COUNTIFS('Functional Test Suite'!$C:$C,$A19,'Functional Test Suite'!$M:$M,"<>") -> 0 | D19: =SUMIF('Functional Test Suite'!$C:$C,$A19,'Functional Test Suite'!$K:$K) -> 18 | E19: =SUMIF('Functional Test Suite'!$C:$C,$A19,'Functional Test Suite'!$O:$O) -> 0 | F19: =IF(D19=0,"",E19/D19) -> 0
A20: 9. Roaming | B20: =COUNTIF('Functional Test Suite'!$C:$C,$A20) -> 6 | C20: =COUNTIFS('Functional Test Suite'!$C:$C,$A20,'Functional Test Suite'!$M:$M,"<>") -> 0 | D20: =SUMIF('Functional Test Suite'!$C:$C,$A20,'Functional Test Suite'!$K:$K) -> 14 | E20: =SUMIF('Functional Test Suite'!$C:$C,$A20,'Functional Test Suite'!$O:$O) -> 0 | F20: =IF(D20=0,"",E20/D20) -> 0
A21: 10. Driver Invoice Payment | B21: =COUNTIF('Functional Test Suite'!$C:$C,$A21) -> 9 | C21: =COUNTIFS('Functional Test Suite'!$C:$C,$A21,'Functional Test Suite'!$M:$M,"<>") -> 0 | D21: =SUMIF('Functional Test Suite'!$C:$C,$A21,'Functional Test Suite'!$K:$K) -> 23 | E21: =SUMIF('Functional Test Suite'!$C:$C,$A21,'Functional Test Suite'!$O:$O) -> 0 | F21: =IF(D21=0,"",E21/D21) -> 0
A22: 11. Reporting and Analytics | B22: =COUNTIF('Functional Test Suite'!$C:$C,$A22) -> 5 | C22: =COUNTIFS('Functional Test Suite'!$C:$C,$A22,'Functional Test Suite'!$M:$M,"<>") -> 0 | D22: =SUMIF('Functional Test Suite'!$C:$C,$A22,'Functional Test Suite'!$K:$K) -> 9 | E22: =SUMIF('Functional Test Suite'!$C:$C,$A22,'Functional Test Suite'!$O:$O) -> 0 | F22: =IF(D22=0,"",E22/D22) -> 0
A23: 12. User Interface | B23: =COUNTIF('Functional Test Suite'!$C:$C,$A23) -> 6 | C23: =COUNTIFS('Functional Test Suite'!$C:$C,$A23,'Functional Test Suite'!$M:$M,"<>") -> 0 | D23: =SUMIF('Functional Test Suite'!$C:$C,$A23,'Functional Test Suite'!$K:$K) -> 10 | E23: =SUMIF('Functional Test Suite'!$C:$C,$A23,'Functional Test Suite'!$O:$O) -> 0 | F23: =IF(D23=0,"",E23/D23) -> 0
... A28: 17. Logging and Audit Trail | B28: =COUNTIF('Functional Test Suite'!$C:$C,$A28) -> 5 | C28: =COUNTIFS('Functional Test Suite'!$C:$C,$A28,'Functional Test Suite'!$M:$M,"<>") -> 0 | D28: =SUMIF('Functional Test Suite'!$C:$C,$A28,'Functional Test Suite'!$K:$K) -> 11 | E28: =SUMIF('Functional Test Suite'!$C:$C,$A28,'Functional Test Suite'!$O:$O) -> 0 | F28: =IF(D28=0,"",E28/D28) -> 0
A29: TOTAL | B29: =SUM(B12:B28) -> 157 | C29: =SUM(C12:C28) -> 0 | D29: =SUM(D12:D28) -> 337 | E29: =SUM(E12:E28) -> 0 | F29: =IF(D29=0,"",E29/D29) -> 0
A32: Non-Functional Category Summary
A33: Category | B33: # Tests | C33: # Scored | D33: Total Weight | E33: Total Weighted Score | F33: Weighted Avg
A34: 1.Certifications, governance, and privacy compliance | B34: =COUNTIF('Non-Functional Test Suite'!$C:$C,$A34) -> 3 | C34: =COUNTIFS('Non-Functional Test Suite'!$C:$C,$A34,'Non-Functional Test Suite'!$M:$M,"<>") -> 0 | D34: =SUMIF('Non-Functional Test Suite'!$C:$C,$A34,'Non-Functional Test Suite'!$K:$K) -> 8 | E34: =SUMIF('Non-Functional Test Suite'!$C:$C,$A34,'Non-Functional Test Suite'!$O:$O) -> 0 | F34: =IF(D34=0,"",E34/D34) -> 0
A35: 2. Security - Identity & Access Management | B35: =COUNTIF('Non-Functional Test Suite'!$C:$C,$A35) -> 5 | C35: =COUNTIFS('Non-Functional Test Suite'!$C:$C,$A35,'Non-Functional Test Suite'!$M:$M,"<>") -> 0 | D35: =SUMIF('Non-Functional Test Suite'!$C:$C,$A35,'Non-Functional Test Suite'!$K:$K) -> 13 | E35: =SUMIF('Non-Functional Test Suite'!$C:$C,$A35,'Non-Functional Test Suite'!$O:$O) -> 0 | F35: =IF(D35=0,"",E35/D35) -> 0
A36: 3. Security - Systems Monitoring | B36: =COUNTIF('Non-Functional Test Suite'!$C:$C,$A36) -> 3 | C36: =COUNTIFS('Non-Functional Test Suite'!$C:$C,$A36,'Non-Functional Test Suite'!$M:$M,"<>") -> 0 | D36: =SUMIF('Non-Functional Test Suite'!$C:$C,$A36,'Non-Functional Test Suite'!$K:$K) -> 8 | E36: =SUMIF('Non-Functional Test Suite'!$C:$C,$A36,'Non-Functional Test Suite'!$O:$O) -> 0 | F36: =IF(D36=0,"",E36/D36) -> 0
A37: 4. Network Security | B37: =COUNTIF('Non-Functional Test Suite'!$C:$C,$A37) -> 5 | C37: =COUNTIFS('Non-Functional Test Suite'!$C:$C,$A37,'Non-Functional Test Suite'!$M:$M,"<>") -> 0 | D37: =SUMIF('Non-Functional Test Suite'!$C:$C,$A37,'Non-Functional Test Suite'!$K:$K) -> 11 | E37: =SUMIF('Non-Functional Test Suite'!$C:$C,$A37,'Non-Functional Test Suite'!$O:$O) -> 0 | F37: =IF(D37=0,"",E37/D37) -> 0
A38: 5. Security - Vulnerability & Patch Management | B38: =COUNTIF('Non-Functional Test Suite'!$C:$C,$A38) -> 3 | C38: =COUNTIFS('Non-Functional Test Suite'!$C:$C,$A38,'Non-Functional Test Suite'!$M:$M,"<>") -> 0 | D38: =SUMIF('Non-Functional Test Suite'!$C:$C,$A38,'Non-Functional Test Suite'!$K:$K) -> 8 | E38: =SUMIF('Non-Functional Test Suite'!$C:$C,$A38,'Non-Functional Test Suite'!$O:$O) -> 0 | F38: =IF(D38=0,"",E38/D38) -> 0
A39: 6. Backup policy | B39: =COUNTIF('Non-Functional Test Suite'!$C:$C,$A39) -> 2 | C39: =COUNTIFS('Non-Functional Test Suite'!$C:$C,$A39,'Non-Functional Test Suite'!$M:$M,"<>") -> 0 | D39: =SUMIF('Non-Functional Test Suite'!$C:$C,$A39,'Non-Functional Test Suite'!$K:$K) -> 6 | E39: =SUMIF('Non-Functional Test Suite'!$C:$C,$A39,'Non-Functional Test Suite'!$O:$O) -> 0 | F39: =IF(D39=0,"",E39/D39) -> 0
A40: 7. Cryptography | B40: =COUNTIF('Non-Functional Test Suite'!$C:$C,$A40) -> 3 | C40: =COUNTIFS('Non-Functional Test Suite'!$C:$C,$A40,'Non-Functional Test Suite'!$M:$M,"<>") -> 0 | D40: =SUMIF('Non-Functional Test Suite'!$C:$C,$A40,'Non-Functional Test Suite'!$K:$K) -> 8 | E40: =SUMIF('Non-Functional Test Suite'!$C:$C,$A40,'Non-Functional Test Suite'!$O:$O) -> 0 | F40: =IF(D40=0,"",E40/D40) -> 0
A41: 8. SDLC - | B41: =COUNTIF('Non-Functional Test Suite'!$C:$C,$A41) -> 3 | C41: =COUNTIFS('Non-Functional Test Suite'!$C:$C,$A41,'Non-Functional Test Suite'!$M:$M,"<>") -> 0 | D41: =SUMIF('Non-Functional Test Suite'!$C:$C,$A41,'Non-Functional Test Suite'!$K:$K) -> 8 | E41: =SUMIF('Non-Functional Test Suite'!$C:$C,$A41,'Non-Functional Test Suite'!$O:$O) -> 0 | F41: =IF(D41=0,"",E41/D41) -> 0
A42: 9. Secure development | B42: =COUNTIF('Non-Functional Test Suite'!$C:$C,$A42) -> 3 | C42: =COUNTIFS('Non-Functional Test Suite'!$C:$C,$A42,'Non-Functional Test Suite'!$M:$M,"<>") -> 0 | D42: =SUMIF('Non-Functional Test Suite'!$C:$C,$A42,'Non-Functional Test Suite'!$K:$K) -> 7 | E42: =SUMIF('Non-Functional Test Suite'!$C:$C,$A42,'Non-Functional Test Suite'!$O:$O) -> 0 | F42: =IF(D42=0,"",E42/D42) -> 0
A43: 10-. Security - Incident Management | B43: =COUNTIF('Non-Functional Test Suite'!$C:$C,$A43) -> 4 | C43: =COUNTIFS('Non-Functional Test Suite'!$C:$C,$A43,'Non-Functional Test Suite'!$M:$M,"<>") -> 0 | D43: =SUMIF('Non-Functional Test Suite'!$C:$C,$A43,'Non-Functional Test Suite'!$K:$K) -> 9 | E43: =SUMIF('Non-Functional Test Suite'!$C:$C,$A43,'Non-Functional Test Suite'!$O:$O) -> 0 | F43: =IF(D43=0,"",E43/D43) -> 0
A44: 6. Business Continuity and Disaster Recovery | B44: =COUNTIF('Non-Functional Test Suite'!$C:$C,$A44) -> 4 | C44: =COUNTIFS('Non-Functional Test Suite'!$C:$C,$A44,'Non-Functional Test Suite'!$M:$M,"<>") -> 0 | D44: =SUMIF('Non-Functional Test Suite'!$C:$C,$A44,'Non-Functional Test Suite'!$K:$K) -> 11 | E44: =SUMIF('Non-Functional Test Suite'!$C:$C,$A44,'Non-Functional Test Suite'!$O:$O) -> 0 | F44: =IF(D44=0,"",E44/D44) -> 0
A45: 11. Scalability | B45: =COUNTIF('Non-Functional Test Suite'!$C:$C,$A45) -> 1 | C45: =COUNTIFS('Non-Functional Test Suite'!$C:$C,$A45,'Non-Functional Test Suite'!$M:$M,"<>") -> 0 | D45: =SUMIF('Non-Functional Test Suite'!$C:$C,$A45,'Non-Functional Test Suite'!$K:$K) -> 3 | E45: =SUMIF('Non-Functional Test Suite'!$C:$C,$A45,'Non-Functional Test Suite'!$O:$O) -> 0 | F45: =IF(D45=0,"",E45/D45) -> 0
... A49: 15. Post Implementation Support | B49: =COUNTIF('Non-Functional Test Suite'!$C:$C,$A49) -> 3 | C49: =COUNTIFS('Non-Functional Test Suite'!$C:$C,$A49,'Non-Functional Test Suite'!$M:$M,"<>") -> 0 | D49: =SUMIF('Non-Functional Test Suite'!$C:$C,$A49,'Non-Functional Test Suite'!$K:$K) -> 7 | E49: =SUMIF('Non-Functional Test Suite'!$C:$C,$A49,'Non-Functional Test Suite'!$O:$O) -> 0 | F49: =IF(D49=0,"",E49/D49) -> 0
A50: TOTAL | B50: =SUM(B34:B49) -> 48 | C50: =SUM(C34:C49) -> 0 | D50: =SUM(D34:D49) -> 123 | E50: =SUM(E34:E49) -> 0 | F50: =IF(D50=0,"",E50/D50) -> 0
